Workbook

Sheet PRESUPUESTO
Q2: Presupuesto / Budget Nº | R2: PS-XXX-2026 PROMCOSER
Q4: Fecha / Date: | R4: 46245
B5: RUC: 20494224314
B6: Mza Ñ lote.3 AH Micaela Bastidas- Marcona
B7: Teléfono: 056-525092
B8: 1.- Cliente / customer
B9: Nombre / Name: | E9: COPREFA CONSTRUCCIONES PRE-FABRICADAS S.R.C. (EPC MARCOBRE) | O9: RUC / VAT ID No.:
B10: Dirección / Address: | E10: MINA JUSTA - CAMPAMENTO JUSTA SUBTERRANEA - ICA | P10: Teléf.. Fax:
B11: Att.:
B12: Proyecto / Project: | E12: AMPLIACION CAMPAMENTO JUSTA SUBTERRANEA
B13: Obra: | E13: SUMINISTRO, INSTALACION, PRUEBAS Y PUESTA EN MARCHA - RAMAL CONTRAINCENDIOS HDPE TIE-IN-06 A GCI
B15: 2.- Alcances y Condiciones / Conditions
C17: Suministro, instalacion, pruebas hidrostaticas y puesta en marcha de un ramal de agua contraincendios en tuberia HDPE, desde el Tie-in-06 hasta el Gabinete Contraincendios (GCI) Tipo III, D=90mm, L=33.75 ml, incluyendo el tramo final en tuberia de acero (riser).
B22: 3.- Precio y Descripción:
B23: Ítem | C23: Descripción / Descripción | O23: Unid | P23: Cantidad | R23: Precio Unit. | T23: Total
P24: QTY | R24: Unit Price
R25: $ | T25: $
C26: =E12 -> AMPLIACION CAMPAMENTO JUSTA SUBTERRANEA | O26: GLB | P26: 1 | R26: =CD!H23 -> 4482.5445 | T26: =+R26*P26 -> 4482.5445
S32: Total $ | T32: =+T26 -> 4482.5445
B33: Son: | C33: Siete mil ochocientos dieciocho con 44/100 DOLARES AMERICANOS (NO INCLUYE IGV) | R33: Gastos Generales | S33: =T33/T32 -> 0.32130354 | T33: =GG!I74 -> 1440.2574
R34: Utilidad | S34: 0.1 | T34: =T32*S34 -> 448.25445
C35: No incluye IGV | R35: Total sin IGV | S35: USD | T35: =T34+T33+T32 -> 6371.0564
B39: 4.- Condiciones de Compra / Terms of Purchase
B41: Moneda/Currency: | E41: =T35 -> 6371.0564 | H41: Soles [S/.] | K41: X | L41: Dólares Americanos [USD] | Q41: Otro:
B43: Tipo de Servicio / Type of Service | G43: x | H43: Suma Alzada | L43: Otro: | M43: Suma Alzada
B45: Forma de Pago/Form of Payment: | G45: PAGO ANTICIPADO O PREVIO ACUERDO
B47: Tiempo de entrega / Delivery time: | G47: 5 dias
B49: Validez de Oferta/Validity of Offer: | G49: 15 Días Calendarios
B51: Lugar / Place | G51: MINA JUSTA - CAMPAMENTO JUSTA SUBTERRANEA - MARCOBRE
B53: Garantía / Warranty | G53: : PROMCOSER garantiza la calidad de los trabajos realizados corrigiendo o reparando los trabajos defectuosos
G54: que sean imputables a PROMCOSER.
B56: Hecho por / Handled by: | F56: A. Cuellar | K56: e-mail: | L56: ventas@promcoser.com.pe | Q56: T.Movil: | R56: 940512282
Q59: Presupuesto / Budget Nº | R59: =+R2 -> PS-XXX-2026 PROMCOSER
Q61: Fecha / Date: | R61: =R4 -> 46245
B62: RUC: 20494224314
B63: Mza ñ lote.3 AH micaela Bastidas- Marcona
B64: Teléfono: 056-525092
B66: 5. Suministros a cargo de PROMCOSER
D69: Suministros a Cargo de PROMCOSER
D70: 5.1. Personal técnico calificado para la ejecución del servicio
...

Sheet CD
C2: PROYECTO : | D2: =PRESUPUESTO!E12 -> AMPLIACION CAMPAMENTO JUSTA SUBTERRANEA
C3: OBRA | D3: =PRESUPUESTO!E13 -> SUMINISTRO, INSTALACION, PRUEBAS Y PUESTA EN MARCHA - RAMAL CONTRAINCENDIOS HDPE TIE-IN-06 A GCI
C4: CLIENTE : | D4: =PRESUPUESTO!E9 -> COPREFA CONSTRUCCIONES PRE-FABRICADAS S.R.C. (EPC MARCOBRE)
C6: ITEM | D6: DESCRIPCION | E6: und | F6: metrado | G6: P.U. $ | H6: Parcial $
D7: SUMINISTRO, INSTALACION, PRUEBAS Y PUESTA EN MARCHA - RAMAL CONTRAINCENDIOS HDPE TIE-IN-06 A GCI
C8: 01 | D8: TRABAJOS PRELIMINARES | H8: =H9 -> 433.13333
C9: 01.01 | D9: MOVILIZACION DE TUBERIA HDPE Y ACCESORIOS | E9: VJE | F9: 1 | G9: =APU!H9 -> 433.13333 | H9: =G9*F9 -> 433.13333
C10: 02 | D10: INSTALACION Y MONTAJE | H10: =H11+H12+H13+H14+H15+H16 -> 3130.5149
C11: 02.01 | D11: TIE-IN A RED EXISTENTE (LOTOTO) Y ARMADO DE CARRETE DE DESMONTAJE | E11: GLB | F11: 1 | G11: =APU!H20 -> 802.589 | H11: =G11*F11 -> 802.589
C12: 02.02 | D12: TENDIDO DE TUBERIA HDPE DENTRO DE ZANJA PREPARADA POR COPREFA | E12: ML | F12: 33.75 | G12: =APU!H36 -> 14.866333 | H12: =G12*F12 -> 501.73875
C13: 02.03 | D13: TERMOFUSION DE JUNTAS HDPE (TRABAJO EN CALIENTE) | E13: UND | F13: 13 | G13: =APU!H48 -> 100.32362 | H13: =G13*F13 -> 1304.2071
C14: 02.04 | D14: FABRICACION DE RISER DE ACERO: CORTE, ESMERILADO Y SOLDADURA | E14: GLB | F14: 1 | G14: =APU!H62 -> 343.6355 | H14: =G14*F14 -> 343.6355
C15: 02.05 | D15: MONTAJE DE VALVULA COMPUERTA Y TRANSICIONES (ARMADO DE JUNTAS BRIDADAS) | E15: UND | F15: 1 | G15: =APU!H81 -> 89.17225 | H15: =G15*F15 -> 89.17225
C16: 02.06 | D16: CONEXION FINAL DE LA TUBERIA AL GABINETE CONTRAINCENDIOS (GCI) EXISTENTE | E16: UND | F16: 1 | G16: =APU!H93 -> 89.17225 | H16: =G16*F16 -> 89.17225
C17: 03 | D17: SERVICIOS SUBCONTRATADOS | H17: =H18 -> 800
C18: 03.01 | D18: PRUEBA HIDROSTATICA SEGUN NFPA 24 - SUBCONTRATADO | E18: GLB | F18: 1 | G18: =APU!H105 -> 800 | H18: =G18*F18 -> 800
C19: 04 | D19: PUESTA EN MARCHA Y CIERRE | H19: =H20+H21+H22 -> 118.89633
C20: 04.01 | D20: COMISIONAMIENTO (APERTURA DE VALVULAS, PURGA DE AIRE, VERIFICACION DE PRESION) | E20: GLB | F20: 1 | G20: =APU!H112 -> 118.89633 | H20: =G20*F20 -> 118.89633
D23: Costo directo | H23: =H8+H10+H17+H19 -> 4482.5445

Sheet APU
A1: ANALISIS DE COSTOS UNITARIOS
A2: PROYECTO: SUMINISTRO, INSTALACION, PRUEBAS Y PUESTA EN MARCHA - RAMAL CONTRAINCENDIOS HDPE TIE-IN-06 A GCI - AMPLIACION CAMPAMENTO JUSTA SUBTERRANEA
A3: CLIENTE: COPREFA CONSTRUCCIONES PRE-FABRICADAS S.R.C. (EPC DE MARCOBRE)
A4: UBICACION: CAMPAMENTO JUSTA SUBTERRANEA - MARCOBRE - ICA
A5: FECHA BASE: 2026-08-11
A6: MONEDA: DOLARES AMERICANOS (US$)
A8: 01.01 MOVILIZACION DE TUBERIA HDPE Y ACCESORIOS
A9: Rendimiento: | B9: 3 | C9: VJE/DIA (GLB) | E9: Unidad: VJE | G9: Costo Unitario: | H9: =H13+H16 -> 433.13333
A10: Insumo | D10: Unidad | E10: Cuadrilla | F10: Cantidad | G10: PU | H10: Parcial
A11: OPERARIO ARMADOR | D11: HH | E11: 1 | F11: =10/B9 -> 3.3333333 | G11: 13.94 | H11: =E11*F11*G11 -> 46.466667
A12: OFICIAL MECANICO | D12: HH | E12: 2 | F12: =10/B9 -> 3.3333333 | G12: 13 | H12: =E12*F12*G12 -> 86.666667
G13: Mano de obra: | H13: =SUM(H11:H12) -> 133.13333
A15: CAMION BARANDA | D15: HM | F15: 4 | G15: 75 | H15: =F15*G15 -> 300
G16: Equipo: | H16: =SUM(H15:H15) -> 300
A19: 02.01 TIE-IN A RED EXISTENTE (LOTOTO) Y ARMADO DE CARRETE DE DESMONTAJE
A20: Rendimiento: | B20: 1 | C20: GLB/DIA | E20: Unidad: GLB | G20: Costo Unitario: | H20: =H25+H28+H32 -> 802.589
A21: Insumo | D21: Unidad | E21: Cuadrilla | F21: Cantidad | G21: PU | H21: Parcial
A22: CAPATAZ | D22: HH | E22: 0.5 | F22: =10/B20 -> 10 | G22: 15.38 | H22: =E22*F22*G22 -> 76.9
A23: OPERARIO ARMADOR | D23: HH | E23: 1 | F23: =10/B20 -> 10 | G23: 13.94 | H23: =E23*F23*G23 -> 139.4
A24: OFICIAL MECANICO | D24: HH | E24: 2 | F24: =10/B20 -> 10 | G24: 13 | H24: =E24*F24*G24 -> 260
G25: Mano de obra: | H25: =SUM(H22:H24) -> 476.3
A27: MATERIALES LOTOTO (CANDADOS, TARJETAS, FORMATOS) | D27: GLB | F27: 1 | G27: 12 | H27: =F27*G27 -> 12
G28: Materiales: | H28: =SUM(H27:H27) -> 12
A30: MAQUINA DE TERMOFUSION HDPE (ALQUILER) | D30: HM | F30: 10 | G30: 30 | H30: =F30*G30 -> 300
A31: HERRAMIENTAS MANUALES | D31: %MO | F31: 3 | G31: =H25 -> 476.3 | H31: =G31*F31/100 -> 14.289
G32: Equipo: | H32: =SUM(H30:H31) -> 314.289
A35: 02.02 TENDIDO DE TUBERIA HDPE DENTRO DE ZANJA PREPARADA POR COPREFA
A36: Rendimiento: | B36: 33 | C36: ML/DIA | E36: Unidad: ML | G36: Costo Unitario: | H36: =H41+H44 -> 14.866333
A37: Insumo | D37: Unidad | E37: Cuadrilla | F37: Cantidad | G37: PU | H37: Parcial
