Workbook
Name Print_Area: APU!$A$1:$F$768
Name Print_Area: CD!$A$1:$H$70
Name Print_Area: GG!$A$1:$I$75
Name Print_Area: METRADO!$A$1:$E$44
Name Print_Area: PRESUPUESTO!$A$1:$V$125
Name Print_Area: 'PS..'!$A$1:$H$51

Sheet PRESUPUESTO
Q2: Presupuesto / Budget Nº | R2: PS-065-2026 PROMCOSER
Q4: Fecha / Date: | R4: 46216
B5: RUC: 20494224314
B6: Mza Ñ lote.3 AH Micaela Bastidas- Marcona
B7: Teléfono: 056-525092
B8: 1.- Cliente / customer
B9: Nombre / Name: | E9: AESA | O9: RUC / VAT ID No.:
B10: Dirección / Address: | E10: AESA | P10: Teléf.. Fax:
B11: Att.:
B12: Proyecto / Project: | E12: PROYECTO: MOV. TIERRAS, FAB. E INSTALACIÓN DE BANCODUCTOS
B15: 2.- Alcances y Condiciones / Conditions
C17: Servicio especializado para infraestructura minera
B22: 3.- Precio y Descripción:
B23: Ítem | C23: Descripción / Descripción | O23: Unid | P23: Cantidad | R23: Precio Unit. | T23: Total
P24: QTY | R24: Unit Price
R25: $ | T25: $
C26: =E12 -> PROYECTO: MOV. TIERRAS, FAB. E INSTALACIÓN DE BANCODUCTOS | O26: GLB | P26: 1 | R26: =CD!H70 -> 123807.96 | T26: =+R26*P26 -> 123807.96
S32: Total $ | T32: =+T26 -> 123807.96
B33: Son: | C33: CIENTO SETENTA Y UN MIL CUATROCIENTOS CUARENTA Y DOS CON 56/100 DOLARES AMERICANOS | R33: Gastos Generales | S33: =T33/T32 -> 0.22029169 | T33: =GG!I74 -> 27273.865
R34: Combustible (Reembolsable) | T34: =COMBUSTIBLE!H12 -> 7979.94
C35: No incluye IGV | R35: Utilidad | S35: 0.1 | T35: =+T32*S35 -> 12380.796
R36: Total sin IGV | S36: USD | T36: =+T35+T33+T32+T34 -> 171442.56
B39: 4.- Condiciones de Compra / Terms of Purchase
B41: Moneda/Currency: | E41: =+T36 -> 171442.56 | H41: Soles [S/.] | K41: X | L41: Dólares Americanos [USD] | Q41: Otro:
B43: Tipo de Servicio / Type of Service | G43: x | H43: Suma Alzada | L43: Otro: | M43: Suma Alzada
B45: Forma de Pago/Form of Payment: | G45: PAGO ANTICIPADO O PREVIO ACUERDO
B47: Tiempo de entrega / Delivery time: | G47: 45 días
B49: Validez de Oferta/Validity of Offer: | G49: 15 Días Calendarios
B51: Lugar / Place | G51: MINA JUSTA - MARCOBRE
B53: Garantía / Warranty | G53: : PROMCOSER garantiza la calidad de los trabajos realizados corrigiendo o reparando los trabajos defectuosos
G54: que sean imputables a PROMCOSER.
B56: Hecho por / Handled by: | F56: A. Cuellar | K56: e-mail: | L56: ventas@promcoser.com.pe | Q56: T.Movil: | R56: 940512282
Q59: Presupuesto / Budget Nº | R59: =+R2 -> PS-065-2026 PROMCOSER
Q61: Fecha / Date: | R61: =R4 -> 46216
B62: RUC: 20494224314
B63: Mza ñ lote.3 AH micaela Bastidas- Marcona
B64: Teléfono: 056-525092
B66: 5. Suministros a cargo de PROMCOSER
D69: Suministros a Cargo de PROMCOSER
D70: 5.1. Personal técnico calificado para la ejecución del servicio
...

Sheet CD
C2: PROYECTO : | D2: =PRESUPUESTO!E12 -> PROYECTO: MOV. TIERRAS, FAB. E INSTALACIÓN DE BANCODUCTOS
C3: CLIENTE : | D3: =PRESUPUESTO!E9 -> AESA
C5: ITEM | D5: DESCRIPCION | E5: und | F5: metrado | G5: P.U. $ | H5: Parcial $
C6: 1 | D6: TRABAJOS PRELIMINARES | H6: =+H7+H8+H9 -> 16740.41
C7: 1.1 | D7: MOVILIZACIÓN Y DESMOVILIZACION DE PERSONAL | E7: MES | F7: 1.5 | G7: 8063.61 | H7: 12095.42
C8: 1.2 | D8: MOVILIZACION Y DESMOVILIZACION DE EQUIPOS, HERRAMIENTAS Y MATERIALES | E8: VJE | F8: 4 | G8: 407.43 | H8: =G8*F8 -> 1629.72
C9: 1.3 | D9: SEGURIDAD Y SEÑALIZACION DE PROYECTO | E9: MES | F9: 1.5 | G9: 2010.18 | H9: 3015.27
C10: 2 | D10: RAMPA ZONA SUR | H10: =+H11+H20+H29+H32 -> 33717.73
C11: 2.1 | D11: BANCO DUCTO EN VÍA | H11: 3490.48
C12: 2.1.1 | D12: EXCAVACIÓN DE ZANJA CON RETROEXCAVADORA 0.6 X 1.00M | E12: M3 | F12: 11.52 | G12: 18.26 | H12: 210.36
C13: 2.1.2 | D13: PERFILADO Y NIVELACION DE TERRENO | E13: ML | F13: 24 | G13: 17.13 | H13: 411.12
C14: 2.1.3 | D14: COLOCACION DE CAMA DE ARENA E=0.20 | E14: ML | F14: 24 | G14: 16.74 | H14: 401.76
C15: 2.1.4 | D15: FABRICACIÓN DE BANCO DUCTOS 0.20 X 0.20 X 1.00M | E15: UND | F15: 24 | G15: 51.47 | H15: 1235.28
C16: 2.1.5 | D16: INSTALACIÓN DE BANCODUCTOS | E16: UND | F16: 24 | G16: 11.41 | H16: 273.84
C17: 2.1.6 | D17: SUMINISTRO DE AFIRMADO | E17: M3 | F17: 5.76 | G17: 48.24 | H17: 277.86
C18: 2.1.7 | D18: RELLENO Y COMPACTACION EN CAPAS DE 200MM | E18: M3 | F18: 11.52 | G18: 43.67 | H18: 503.08
C19: 2.1.8 | D19: ELIMINACION DE MATERIAL EXCEDENTE D= 5 KM | E19: M3 | F19: 11.52 | G19: 15.38 | H19: 177.18
C20: 2.2 | D20: BANCO DUCTO EN CAMINO | H20: 23269.83
C21: 2.2.1 | D21: EXCAVACIÓN DE ZANJA CON RETROEXCAVADORA 0.60 X 0.80M | E21: M3 | F21: 76.8 | G21: 18.26 | H21: 1402.37
C22: 2.2.2 | D22: PERFILADO Y NIVELACION DE TERRENO | E22: ML | F22: 160 | G22: 17.13 | H22: 2740.8
C23: 2.2.3 | D23: COLOCACION DE CAMA DE ARENA E=0.20 | E23: ML | F23: 160 | G23: 16.74 | H23: 2678.4
C24: 2.2.4 | D24: FABRICACIÓN DE BANCO DUCTOS 0.20 X 0.20 X 1.00M | E24: UND | F24: 160 | G24: 51.47 | H24: 8235.2
C25: 2.2.5 | D25: INSTALACIÓN DE BANCODUCTOS | E25: UND | F25: 160 | G25: 11.41 | H25: 1825.6
C26: 2.2.6 | D26: SUMINISTRO DE AFIRMADO | E26: M3 | F26: 38.4 | G26: 48.24 | H26: 1852.42
C27: 2.2.7 | D27: RELLENO Y COMPACTACION EN CAPAS DE 200MM | E27: M3 | F27: 76.8 | G27: 43.67 | H27: 3353.86
C28: 2.2.8 | D28: ELIMINACION DE MATERIAL EXCEDENTE D= 5 KM | E28: M3 | F28: 76.8 | G28: 15.38 | H28: 1181.18
C29: 2.3 | D29: CAJAS DE REGISTRO | H29: 2602.48
C30: 2.3.1 | D30: SUMINISTRO DE BUZON DE PASO 0.60 X 0.60 X 0.80M | E30: UND | F30: 8 | G30: 269.83 | H30: 2158.64
C31: 2.3.2 | D31: INSTALACIÓN DE BUZON DE PASO | E31: UND | F31: 8 | G31: 55.48 | H31: 443.84
C32: 2.4 | D32: TENDIDO DE TUBERIA FLEXIBLE | H32: 4354.94
C33: 2.4.1 | D33: SUMINISTRO TUBERÍA CONDUIT FLEXIBLE CON FORRO DE PVC LIQUID TIGHT 2″ Y ACCESORIOS | E33: GLB | F33: 1 | G33: 2658.74 | H33: 2658.74
C34: 2.4.2 | D34: INSTALACIÓN DE TUBERIA FLEXIBLE | E34: ML | F34: 165 | G34: 10.28 | H34: 1696.2
C35: 3 | D35: RAMPA ZONA NORTE | H35: =+H36+H45+H54+H57 -> 38703.02
C36: 3.1 | D36: BANCO DUCTO EN VÍA | H36: 3782.59
C37: 3.1.1 | D37: EXCAVACIÓN DE ZANJA CON RETROEXCAVADORA 0.60 X 1.00M | E37: M3 | F37: 14.4 | G37: 18.26 | H37: 262.94
C38: 3.1.2 | D38: PERFILADO Y NIVELACION DE TERRENO | E38: ML | F38: 24 | G38: 17.13 | H38: 411.12
C39: 3.1.3 | D39: COLOCACION DE CAMA DE ARENA E=0.20 | E39: ML | F39: 24 | G39: 16.74 | H39: 401.76
C40: 3.1.4 | D40: FABRICACIÓN DE BANCO DUCTOS 0.20 X 0.20 X 1.00M | E40: UND | F40: 24 | G40: 51.47 | H40: 1235.28
C41: 3.1.5 | D41: INSTALACIÓN DE BANCODUCTOS | E41: UND | F41: 24 | G41: 11.41 | H41: 273.84
C42: 3.1.6 | D42: SUMINISTRO DE AFIRMADO | E42: M3 | F42: 7.2 | G42: 48.24 | H42: 347.33
...

Sheet APU
A1: ANALISIS DE COSTOS UNITARIOS
A2: PROYECTO: MOV. TIERRAS, FAB. E INSTALACIÓN DE BANCODUCTOS - AESA
A3: CLIENTE: AESA
A4: UBICACION: MINA JUSTA - ICA - NASCA - MARCONA
A5: FECHA BASE: 2026-04-15
A6: MONEDA: DOLARES
A8: 1.1 MOVILIZACIÓN Y DESMOVILIZACION DE PERSONAL
A9: Rendimiento: 1.0000 MES/DIA | C9: Unidad: MES | E9: Costo Unitario: | F9: 8063.61
A10: Insumo | B10: Unidad | C10: Cuadrilla | D10: Cantidad | E10: PU | F10: Parcial
A11: CONDUCTOR | B11: MES | C11: 0 | D11: 3 | E11: 1187.87 | F11: 3563.61
E12: Mano de obra: | F12: 3563.61
A14: PETROLEO | B14: GAL | D14: 0 | E14: 5.1 | F14: 0
E15: Materiales: | F15: 0
A17: CAMIONETA PICK UP | B17: MES | C17: 0 | D17: 1 | E17: 1800 | F17: 1800
A18: MINIVAN 14 PASAJEROS | B18: MES | C18: 0 | D18: 1 | E18: 2700 | F18: 2700
E19: Equipo: | F19: 4500
A20: CONDUCTOR | B20: HH | C20: 1 | D20: 624 | E20: 0 | F20: 0
E21: Mano de obra: | F21: 0
A23: 1.2 MOVILIZACION Y DESMOVILIZACION DE EQUIPOS, HERRAMIENTAS Y MATERIALES
A24: Rendimiento: 2.0000 VJE/DIA | C24: Unidad: VJE | E24: Costo Unitario: | F24: =+F29+F33 -> 407.43
A25: Insumo | B25: Unidad | C25: Cuadrilla | D25: Cantidad | E25: PU | F25: Parcial
A26: CAPATAZ. | B26: HH | C26: 0.1 | D26: 0.4 | E26: 15.38 | F26: 6.15
A27: OPERADOR DE EQUIPO LIVIANO | B27: HH | C27: 1 | D27: 4 | E27: 13.46 | F27: 53.84
A28: VIGIA | B28: HH | C28: 1 | D28: 4 | E28: 11.86 | F28: 47.44
E29: Mano de obra: | F29: 107.43
A32: CAMION BARANDA | B32: HM | C32: 1 | D32: 4 | E32: 75 | F32: 300
E33: Equipo: | F33: 300
A36: 1.3 SEGURIDAD Y SEÑALIZACION DE PROYECTO
A37: Rendimiento: 1.0000 ME/DIA | C37: Unidad: ME | E37: Costo Unitario: | F37: 2010.18
A38: Insumo | B38: Unidad | C38: Cuadrilla | D38: Cantidad | E38: PU | F38: Parcial
A39: CAPATAZ | B39: MES | C39: 0 | D39: 0.1 | E39: 1484.84 | F39: 148.48
A40: OPERARIO | B40: MES | C40: 0 | D40: 0.5 | E40: 1272.72 | F40: 636.36
E41: Mano de obra: | F41: 784.84
A43: SEÑALETICA INFORMATIVA | B43: UND | D43: 15 | E43: 22.8 | F43: 342
A44: CABALLETES | B44: UND | D44: 5 | E44: 14.4 | F44: 72
A45: CONOS DE SEÑALIZACION | B45: UND | D45: 30 | E45: 10.8 | F45: 324
A46: BARRAS RETRACTILES | B46: UND | D46: 30 | E46: 8.77 | F46: 263.1
A47: BATERIA DE RESIDUOS SOLIDOS | B47: GLB | D47: 1 | E47: 65 | F47: 65
A48: ESTACION DE EMERGENCIA | B48: GLB | D48: 1 | E48: 120 | F48: 120
E49: Materiales: | F49: 1186.1
...

Sheet PS..
C2: PROYECTO : | D2: =+PRESUPUESTO!C26 -> PROYECTO: MOV. TIERRAS, FAB. E INSTALACIÓN DE BANCODUCTOS
C3: CLIENTE : | D3: MARCOBRE - MINA JUSTA
C4: EJECUCION : | D4: 30 | E4: Dias
F5: =8175/30 -> 272.5
C6: ITEM | D6: DESCRIPCION | E6: UND | F6: METRADO | G6: P.U.$ | H6: Parcial $
C7: 01 | D7: OBRAS PRELIMINARES | H7: =SUM(H8:H12) -> #REF!
C8: 01.01 | D8: MOVILIZACION Y DESMOVILIZACION DE PERSONAL | E8: mes | F8: 1 | G8: 8175 | H8: =G8*F8 -> 8175
C9: 01.02 | D9: MOVILIZACION Y DESMOVILIZACION DE EQUIPOS, HERRAMIENTAS Y MATERIALES | E9: vje | F9: 1 | G9: 479.06 | H9: =G9*F9 -> 479.06
C10: 01.03 | D10: SEGURIDAD Y SEÑALIZACION DE OBRA | E10: glb | F10: 1 | G10: 2615.85 | H10: =G10*F10 -> 2615.85
C11: 01.04 | D11: MOVILIZACIÓN Y DESMOVILIZACIÓN DE MANLIFT | E11: vje | F11: 2 | G11: =APU!#REF! -> #REF! | H11: =G11*F11 -> #REF!
C12: 01.05 | D12: ALQUILER DE MANLITF (Inc. Operador) | E12: día | F12: 30 | G12: =APU!#REF! -> #REF! | H12: =G12*F12 -> #REF!
C13: 02 | D13: INSTALACION DE PUERTA DE INGRESO | H13: =SUM(H14:H17) -> 947.01
C14: 02.01 | D14: ARMADO Y DESARMADO DE TORRE DE ANDAMIOS x 2 CUERPOS HERMETIZADO | E14: día | F14: 2 | G14: 97.18 | H14: =+G14*F14 -> 194.36
C15: 02.02 | D15: RETIRO Y ELIMINACION DE ESTRUCTURA DAÑADA | E15: kg | F15: 20 | G15: 0.69 | H15: =+G15*F15 -> 13.8
C16: 02.03 | D16: FABRICACION DE PUERTA METALICA 1.6x2.1 mt (Inc. Chapa y accesorios) | E16: und | F16: 1 | G16: 563.05 | H16: =+G16*F16 -> 563.05
C17: 02.04 | D17: INSTALACION DE PUERTA METALICA Y ACCESORIOS | E17: kg | F17: 60 | G17: 2.93 | H17: =+G17*F17 -> 175.8
C18: 03 | D18: CIERRE DE ACCESOS | H18: =SUM(H19:H23) -> 1606.2
C19: 03.01 | D19: ARMADO Y DESARMADO DE TORRE DE ANDAMIOS x 2 CUERPOS | E19: día | F19: 2 | G19: 176.6 | H19: =G19*F19 -> 353.2
C20: 03.02 | D20: FABRICACION DE ESTRUCTURA LIVIANA INOXIDABLE | E20: kg | F20: 40 | G20: 12.68 | H20: =G20*F20 -> 507.2
C21: 03.03 | D21: MONTAJE DE ESTRUCTURA LIVIANA | E21: kg | F21: 40 | G21: 2.3 | H21: =G21*F21 -> 92
C22: 03.04 | D22: SUMINISTRO DE LONA PLAST DG1330-BO | E22: m2 | F22: 20 | G22: MCB
C23: 03.05 | D23: INSTALACION DE LONAPLAST DG1330 - BO | E23: m2 | F23: 20 | G23: 32.69 | H23: =G23*F23 -> 653.8
C24: 04 | D24: MANTENIMIENTO ESTRUCTURAL - PUERTAS CORREDIZAS | H24: =+SUM(H25:H34) -> 10027.93
C25: 04.01 | D25: ARMADO Y DESARMADO DE TORRE DE ANDAMIOS x 6 CUERPOS | E25: día | F25: 8 | G25: 218.59 | H25: =+G25*F25 -> 1748.72
C26: 04.02 | D26: RETIRO Y REINSTALACION DE LONA PLAST DG1330-BO | E26: m2 | F26: 100 | G26: 4.55 | H26: =+G26*F26 -> 455
C27: 04.03 | D27: LIMPIEZA MANUAL CON EQUIPOS | E27: m2 | F27: 60 | G27: 17.49 | H27: =+G27*F27 -> 1049.4
C28: 04.04 | D28: APLICACION DE PINTURA BASE ESMALTE EPOXICO JET 70 MP | E28: m2 | F28: 60 | G28: 24.96 | H28: =+G28*F28 -> 1497.6
C29: 04.05 | D29: APLICACION DE PINTURA ACABADO POLIURETANO JETHANE 650 HS | E29: m2 | F29: 60 | G29: 17.73 | H29: =+G29*F29 -> 1063.8
C30: 04.06 | D30: REEMPLAZO DE CABLE ACERADO PARA PUERTA CORREDIZA | E30: m | F30: 100 | G30: 6.97 | H30: =+G30*F30 -> 697
C31: 04.07 | D31: REEMPLAZO DE RIEL GUIA PARA PUERTA CORREDIZA | E31: m | F31: 50 | G31: 43.78 | H31: =+G31*F31 -> 2189
C32: 04.08 | D32: REEMPLAZO DE POLEAS PARA PUERTAS CORREDIZAS | E32: und | F32: 32 | G32: 26.02 | H32: =+G32*F32 -> 832.64
C33: 04.09 | D33: REEMPLAZO DE WINCHES MANUALES 800 LB | E33: und | F33: 4 | G33: 89.88 | H33: =+G33*F33 -> 359.52
C34: 04.10 | D34: REPARACION DE MANIVELAS Y PESTILLOS MENORES | E34: und | F34: 5 | G34: 27.05 | H34: =+G34*F34 -> 135.25
C35: 05 | D35: HERMETIZACION DE TECHOS | H35: =SUM(H36:H37) -> 1961.4
C36: 05.01 | D36: SUMINISTRO DE LONA PLAST DG1330-BO | E36: m2 | F36: 60 | G36: MCB
C37: 05.02 | D37: INSTALACION DE LONAPLAST DG1330 - BO | E37: m2 | F37: 60 | G37: 32.69 | H37: =+G37*F37 -> 1961.4
C38: 06 | D38: LIMPIEZA DE COBERTORES TRANSLUCIDAS - TECHO ALMACEN CENTRAL | H38: =SUM(H39:H40) -> #REF!
C39: 06.01 | D39: LIMPIEZA DE COBERTORES DE TECHI | E39: Und | F39: 12 | G39: =APU!#REF! -> #REF! | H39: =+G39*F39 -> #REF!
C40: 06.02 | D40: LIMPIEZA DE ACCESOS POSTLAVADO | E40: ml | F40: 110 | G40: =APU!#REF! -> #REF! | H40: =+G40*F40 -> #REF!
C41: 07 | D41: INSTALACION DE EXTRACTORES EOLICOS - TECHO ALMACEN CENTRAL | H41: =SUM(H42:H43) -> #REF!
...

Sheet GG
B2: ANALISIS DE GASTOS GENERALES (PROYECTOS MENORES)
B4: PROYECTO: | C4: =+'PS..'!D2 -> PROYECTO: MOV. TIERRAS, FAB. E INSTALACIÓN DE BANCODUCTOS
B5: OBRA: | C5: =+C4 -> PROYECTO: MOV. TIERRAS, FAB. E INSTALACIÓN DE BANCODUCTOS
B6: CONTRATISTA: | C6: PROMCOSER SRL
B7: FECHA: | C7: 46133
B8: PLAZO PROYECTO (MESES): | D8: 1.5
B11: ANALISIS DE GASTOS GENERALES
B12: Item | C12: DESCRIPCION | D12: UND | E12: CAN. | F12: MES | H12: PARCIAL | I12: TOTAL
G13: SALARIO BAS. MES | H13: COSTO MENSUAL incluye BB.SS.
G15: $. | H15: $. | I15: $.
B16: 1 | C16: ÁREA TÉCNICA
C17: Residente de Obra | D17: mes | E17: 1 | F17: 0 | G17: 2300 | H17: =+G17*1.45 -> 3335 | I17: =E17*F17*H17 -> 0
C18: Ingeniero de Calidad | D18: mes | E18: 1.5 | F18: 1 | G18: =6031.4/3.4 -> 1773.9412 | H18: =+G18*1.45 -> 2572.2147 | I18: =E18*F18*H18 -> 3858.3221
C19: Ingeniero de oficina tecnica | D19: mes | E19: 1 | F19: 0.5 | G19: =6000/3.3 -> 1818.1818 | H19: =+G19*1.45 -> 2636.3636 | I19: =E19*F19*H19 -> 1318.1818
C20: Relevo de supervision | D20: mes | E20: 1.5 | F20: 1 | G20: =5125.11/3.45 -> 1485.5391 | H20: =+G20*1.45 -> 2154.0317 | I20: =E20*F20*H20 -> 3231.0476
C21: Ingeniero de seguridad | D21: mes | E21: 1.5 | F21: 1 | G21: =4714.51/3.4 -> 1386.6206 | H21: =+G21*1.45 -> 2010.5999 | I21: =E21*F21*H21 -> 3015.8998
E23: =SUM(E17:E22) -> 6.5 | H23: 1 | I23: =SUM(I17:I22) -> 11423.451
B24: 2 | C24: EMPLEADO
C25: CONDUCTOR | D25: mes | E25: 1 | F25: 0.5 | G25: 757.58 | H25: =+G25*1.45 -> 1098.491 | I25: =E25*F25*H25 -> 549.2455
C26: ALMACEN | D26: mes | E26: 1 | F26: 0.5 | G26: 757.58 | H26: =+G26*1.45 -> 1098.491 | I26: =E26*F26*H26 -> 549.2455
E29: =SUM(E25:E28) -> 2 | H29: 2 | I29: =SUM(I25:I28) -> 1098.491
B30: 3 | C30: VEHICULOS: CAMIONETAS, BUSES.
C31: Vehiculos | G31: COSTO $.
C32: Camioneta incluye combustible | D32: mes | E32: 1 | F32: 0.5 | G32: =60*30 -> 1800 | I32: =E32*G32*F32 -> 900
C33: Bus Movilidad a Obra incluye combustible | D33: mes | E33: 1 | F33: 0.5 | G33: =120*5.1 -> 612 | I33: =E33*G33*F33 -> 306
H35: 3 | I35: =SUM(I31:I34) -> 1206
B36: 4 | C36: SEGURIDAD
C37: Implementos seguridad (solo staff de ingenieros, EPP de obreros debe ser considerada en el costo de horas hombre dentro del costo directo) | D37: Pers | E37: 2 | G37: =350/3 -> 116.66667 | I37: =E37*G37 -> 233.33333
C38: Exámenes Médicos Ocupacional (Staff y obreros) | D38: Pers | E38: 2 | G38: =284/3.4/3 -> 27.843137 | I38: =E38*G38 -> 55.686275
C39: Pruebas y ensayos | D39: Glb | E39: 1 | G39: 400 | I39: =E39*G39 -> 400
C40: Cursos y Capacitaciones | D40: Pers | E40: 2 | G40: =560/3.4/3 -> 54.901961 | I40: =E40*G40 -> 109.80392
C41: Cursos Basicos portuarios: PBIP Basico Seguridad portuaria Mercancias peligrosas | D41: Pers | G41: =45*3 -> 135 | I41: =E41*G41 -> 0
C42: Gestion Portuaria: Gestion de seguridad portuaria Gestion de mercancias peligrosas | D42: Pers | G42: 176 | I42: =E42*G42 -> 0
H45: 4 | I45: =SUM(I37:I44) -> 798.82353
B46: 5 | C46: EQUIPOS: OFICINA, COMPUTO, COMUNICACIONES. | E46: Cant | F46: Incidencia | G46: COSTO/mes
C47: Equipos
C48: computadoras completas | E48: 2 | F48: 0.3 | G48: 484.84848 | I48: =G48*F48*E48 -> 290.90909
C49: telefono celular | E49: 2 | F49: 1 | G49: 27.272727 | I49: =G49*F49*E49 -> 54.545455
C51: Equipos de Campamentos
C52: alquiler de vivienda para staff | E52: 2 | F52: 1 | G52: 151.51515 | I52: =G52*F52*E52 -> 303.0303
...

Sheet COMBUSTIBLE
A2: ITEM | B2: DESCRIPCION DEL EQUIPO | C2: CANTIDAD DE EQUIPOS | D2: CONSUMO (Gln/ HE) | E2: HORA MINIMA | F2: UND | G2: METRADO | H2: CONSUMO PARCIAL
A3: 01 | B3: Retroexcavadora | C3: 1 | D3: 2 | E3: 6 | F3: Dias | G3: 45 | H3: =E3*D3*C3*G3 -> 540
A4: 02 | B4: Camioneta | C4: 1 | D4: 1 | E4: 120 | F4: Mes | G4: 1.5 | H4: =E4*D4*C4*G4 -> 180
A5: 03 | B5: Minivan | C5: 1 | D5: 1 | E5: 120 | F5: Mes | G5: 1.5 | H5: =E5*D5*C5*G5 -> 180
A6: 04 | B6: Volquete 20m3 | C6: 1 | D6: 5 | E6: 4 | F6: vje | G6: 26 | H6: =E6*D6*C6*G6 -> 520
A7: 05 | B7: Camión | C7: 1 | D7: 4 | E7: 4 | F7: vje | G7: 12 | H7: =E7*D7*C7*G7 -> 192
A8: 06 | B8: Vibroapisonador | C8: 1 | D8: 0.25 | E8: 6 | F8: Dias | G8: 30 | H8: =E8*D8*C8*G8 -> 45
A9: 07 | B9: Minicargador | C9: 1 | D9: 1.5 | E9: 6 | F9: Dias | G9: 45 | H9: =E9*D9*C9*G9 -> 405
F10: TOTAL CONSUMO / GALONES | H10: =SUM(H3:H9) -> 2062
F12: Costo por combustile (reembolsable) | H12: =H10*3.87 -> 7979.94
F13: GG | G13: 0.1 | H13: =H12*G13 -> 797.994
F14: UTILIDAD | G14: 0.1 | H14: =G14*H12 -> 797.994
F15: TOTAL SIN IGV | H15: =+H14+H13+H12 -> 9575.928

Sheet METRADO
B2: RAMPA SUR
B3: N° | C3: DESCRIPCIÓN | D3: Unidad | E3: Metrado
B4: 1 | C4: Bancoducto en vía
B5: 1.1 | C5: Excavación de zanja 0.60 x 1.00m | D5: m3 | E5: =0.6*0.8*24 -> 11.52
B6: 1.2 | C6: Bancoducto de 1.00m | D6: und | E6: 24
B7: 1.3 | C7: Tubería de PVC SAP 2" | D7: m | E7: 24
B8: 1.5 | C8: Suministro de cable coaxial - AESA | D8: m | E8: 30
B10: 2 | C10: Bancoducto en camino
B11: 2.1 | C11: Excavación de zanja 0.60 x 0.80m | D11: m3 | E11: =0.6*0.8*160 -> 76.8
B12: 2.2 | C12: Bancoducto de 1.00 | D12: und | E12: 160
B13: 2.3 | C13: Tubería de PVC SAP 2" | D13: m | E13: 160
B14: 2.5 | C14: Suministro de cable coaxial - AESA | D14: m | E14: 166
B16: 3 | C16: Cajas de registro | F16: =E8+E14+E20+E30+E36+E42 -> 765
B17: 3.1 | C17: Buzón de paso 0.8 x 0.8 x 0.8 | D17: und | E17: 8
B19: 4 | C19: Cable coaxial x tub flexible
B20: 4.1 | C20: Suministro de cable coaxial - AESA | D20: m | E20: 165
B21: 4.2 | C21: Tubería metalica 2" | D21: m | E21: 165
B22: 4.3 | C22: Alcayata | D22: und | E22: 30
B24: RAMPA NORTE
B25: N° | C25: DESCRIPCIÓN | D25: Unidad | E25: Metrado
B26: 1 | C26: Bancoducto en vía
B27: 1.1 | C27: Excavación de zanja de 0.60 x 1.00m | D27: m3 | E27: =0.6*1*24 -> 14.4
B28: 1.2 | C28: Bancoducto | D28: und | E28: 24
B29: 1.3 | C29: Tubería de PVC SAP 2" | D29: m | E29: 24
B30: 1.5 | C30: Suministro de cable coaxial - AESA | D30: m | E30: 30
B32: 2 | C32: Bancoducto en camino
B33: 2.1 | C33: Excavación de zanja de 0.60 x 0.80 m | D33: m3 | E33: =0.6*0.8*E35 -> 92.16
B34: 2.2 | C34: Bancoducto | D34: und | E34: 192
B35: 2.3 | C35: Tubería de PVC SAP 2" | D35: m | E35: 192
B36: 2.5 | C36: Suministro de cable coaxial - AESA | D36: m | E36: 198
B38: 3 | C38: Cajas de registro
B39: 3.1 | C39: Buzón de paso 0.60 x 0.60 x 0.8 m3 | D39: und | E39: 8
B41: 4 | C41: Cable coaxial x tub flexible
B42: 4.1 | C42: Suministro de cable coaxial - AESA | D42: m | E42: 176
B43: 4.2 | C43: Tubería metalica 2" | D43: m | E43: 170
B44: 4.3 | C44: Alcayata | D44: und | E44: 35

Sheet Ajuste HH MOD
A1: AJUSTE DE HH DE MANO DE OBRA DIRECTA (MOD) -- PS-065 Bancoductos
A2: Generado: 2026-09-15. Revisado con Victor a partir de 3 fuentes: hoja APU (visible), Listado de Insumos - AESA.xlsx, y la regla MES->HH (factor 208 HH/mes) definida el 2026-09-06.
A3: Objetivo: la suma de HH por partida y la suma de HH por cargo deben coincidir en el TOTAL REAL: 5,312.08 HH.
A4: IMPORTANTE: las filas marcadas ESTIMADO son un prorrateo por peso en dolares (Sub Partidas de concreto+encofrado), no vienen desglosadas por partida en ningun archivo fuente -- si AESA/PROMCOSER entrega el analisis real de esas sub-partidas, estos numeros deben corregirse.
A6: TABLA 1 -- HH por PARTIDA
A7: WBS | B7: Descripcion | C7: Metrado | D7: HH visible en APU | E7: HH ajuste | F7: Tipo de ajuste | G7: HH TOTAL partida
A8: 1.1 | B8: MOVILIZACIÓN Y DESMOVILIZACION DE PERSONAL | C8: 1.5 | D8: 0 | E8: 936 | F8: EXACTO (MES->HH, factor 208, CONDUCTOR) | G8: 936
A9: 1.2 | B9: MOVILIZACION Y DESMOVILIZACION DE EQUIPOS, HERRAMIENTAS Y MATERIALES | C9: 4 | D9: 33.6 | E9: 0 | G9: 33.6
A10: 1.3 | B10: SEGURIDAD Y SEÑALIZACION DE PROYECTO | C10: 1.5 | D10: 0 | E10: 187.2 | F10: EXACTO (MES->HH, factor 208, CAPATAZ+OPERARIO) | G10: 187.2
A11: 2.1.1 | B11: EXCAVACIÓN DE ZANJA CON RETROEXCAVADORA 0.6 X 1.00M | C11: 11.52 | D11: 6.45 | E11: 0 | G11: 6.45
A12: 2.1.2 | B12: PERFILADO Y NIVELACION DE TERRENO | C12: 24 | D12: 20.16 | E12: 0 | G12: 20.16
A13: 2.1.3 | B13: COLOCACION DE CAMA DE ARENA E=0.20 | C13: 24 | D13: 6.72 | E13: 0 | G13: 6.72
A14: 2.1.4 | B14: FABRICACIÓN DE BANCO DUCTOS 0.20 X 0.20 X 1.00M | C14: 24 | D14: 0 | E14: 44.87 | F14: ESTIMADO (prorrateo Sub Partidas concreto+encofrado) | G14: 44.87
A15: 2.1.5 | B15: INSTALACIÓN DE BANCODUCTOS | C15: 24 | D15: 14.88 | E15: 0 | G15: 14.88
A16: 2.1.6 | B16: SUMINISTRO DE AFIRMADO | C16: 5.76 | D16: 1.15 | E16: 0 | G16: 1.15
A17: 2.1.7 | B17: RELLENO Y COMPACTACION EN CAPAS DE 200MM | C17: 11.52 | D17: 31.49 | E17: 0 | G17: 31.49
A18: 2.1.8 | B18: ELIMINACION DE MATERIAL EXCEDENTE D= 5 KM | C18: 11.52 | D18: 3.46 | E18: 0 | G18: 3.46
A19: 2.2.1 | B19: EXCAVACIÓN DE ZANJA CON RETROEXCAVADORA 0.60 X 0.80M | C19: 76.8 | D19: 43.02 | E19: 0 | G19: 43.02
A20: 2.2.2 | B20: PERFILADO Y NIVELACION DE TERRENO | C20: 160 | D20: 134.4 | E20: 0 | G20: 134.4
A21: 2.2.3 | B21: COLOCACION DE CAMA DE ARENA E=0.20 | C21: 160 | D21: 44.78 | E21: 0 | G21: 44.78
A22: 2.2.4 | B22: FABRICACIÓN DE BANCO DUCTOS 0.20 X 0.20 X 1.00M | C22: 160 | D22: 0 | E22: 299.14 | F22: ESTIMADO (prorrateo Sub Partidas concreto+encofrado) | G22: 299.14
A23: 2.2.5 | B23: INSTALACIÓN DE BANCODUCTOS | C23: 160 | D23: 99.2 | E23: 0 | G23: 99.2
A24: 2.2.6 | B24: SUMINISTRO DE AFIRMADO | C24: 38.4 | D24: 7.68 | E24: 0 | G24: 7.68
A25: 2.2.7 | B25: RELLENO Y COMPACTACION EN CAPAS DE 200MM | C25: 76.8 | D25: 209.93 | E25: 0 | G25: 209.93
A26: 2.2.8 | B26: ELIMINACION DE MATERIAL EXCEDENTE D= 5 KM | C26: 76.8 | D26: 23.04 | E26: 0 | G26: 23.04
A27: 2.3.1 | B27: SUMINISTRO DE BUZON DE PASO 0.60 X 0.60 X 0.80M | C27: 8 | D27: 0 | E27: 72.97 | F27: ESTIMADO (prorrateo Sub Partidas concreto+encofrado, sin acero) | G27: 72.97
A28: 2.3.2 | B28: INSTALACIÓN DE BUZON DE PASO | C28: 8 | D28: 25.6 | E28: 0 | G28: 25.6
A29: 2.4.1 | B29: SUMINISTRO TUBERÍA CONDUIT FLEXIBLE CON FORRO DE PVC LIQUID TIGHT 2″ Y ACCESORIOS | C29: 1 | D29: 8 | E29: 0 | G29: 8
A30: 2.4.2 | B30: INSTALACIÓN DE TUBERIA FLEXIBLE | C30: 165 | D30: 110.88 | E30: 0 | G30: 110.88
A31: 3.1.1 | B31: EXCAVACIÓN DE ZANJA CON RETROEXCAVADORA 0.60 X 1.00M | C31: 14.4 | D31: 8.07 | E31: 0 | G31: 8.07
A32: 3.1.2 | B32: PERFILADO Y NIVELACION DE TERRENO | C32: 24 | D32: 20.16 | E32: 0 | G32: 20.16
A33: 3.1.3 | B33: COLOCACION DE CAMA DE ARENA E=0.20 | C33: 24 | D33: 6.72 | E33: 0 | G33: 6.72
A34: 3.1.4 | B34: FABRICACIÓN DE BANCO DUCTOS 0.20 X 0.20 X 1.00M | C34: 24 | D34: 0 | E34: 44.87 | F34: ESTIMADO (prorrateo Sub Partidas concreto+encofrado) | G34: 44.87
A35: 3.1.5 | B35: INSTALACIÓN DE BANCODUCTOS | C35: 24 | D35: 14.88 | E35: 0 | G35: 14.88
A36: 3.1.6 | B36: SUMINISTRO DE AFIRMADO | C36: 7.2 | D36: 1.44 | E36: 0 | G36: 1.44
A37: 3.1.7 | B37: RELLENO Y COMPACTACION EN CAPAS DE 200MM | C37: 14.4 | D37: 39.36 | E37: 0 | G37: 39.36
A38: 3.1.8 | B38: ELIMINACION DE MATERIAL EXCEDENTE D= 5 KM | C38: 14.4 | D38: 4.32 | E38: 0 | G38: 4.32
A39: 3.2.1 | B39: EXCAVACIÓN DE ZANJA CON RETROEXCAVADORA 0.60 X 0.80M | C39: 92.16 | D39: 51.62 | E39: 0 | G39: 51.62
A40: 3.2.2 | B40: PERFILADO Y NIVELACION DE TERRENO | C40: 192 | D40: 161.28 | E40: 0 | G40: 161.28
A41: 3.2.3 | B41: COLOCACION DE CAMA DE ARENA E=0.20 | C41: 192 | D41: 53.74 | E41: 0 | G41: 53.74
...
